<?xml version="1.0"?>

<robot xmlns:xacro="http://www.ros.org/wiki/xacro" name="bot_wheel">
  <xacro:macro name="scout_wheel" params="wheel_prefix *joint_pose  *axis">
    <link name="${wheel_prefix}_wheel_link">
      <inertial>
        <mass value="3" />
        <origin xyz="0 0 0" />
        <inertia ixx="0.7171" ixy="0"      ixz="0" 
                              iyy="0.1361" iyz="0" 
                                           izz="0.7171" />
      </inertial>
      <visual>
        <origin xyz="0 0 0" rpy="0 0 0" />
        <geometry>
          <mesh filename="package://bot_description/meshes/wheel.dae" />
        </geometry>
      </visual>
      <collision>
        <origin xyz="0 0 0" rpy="${M_PI/2} 0 0" />
        <geometry>
          <cylinder length="${wheel_length}" radius="${wheel_radius}" />
        </geometry>
      </collision>
    </link>

    <joint name="${wheel_prefix}_wheel" type="continuous">
      <parent link="base_link"/>
      <child link="${wheel_prefix}_wheel_link"/>
      <xacro:insert_block name="joint_pose"/>
      <xacro:insert_block name="axis"/>
    </joint>  

	<transmission name="${wheel_prefix}_wheel_trans" >
	  <type>transmission_interface/SimpleTransmission</type>
	  <actuator name="${wheel_prefix}_wheel_motor">
	    <mechanicalReduction>1</mechanicalReduction>
	  </actuator>
	  <joint name="${wheel_prefix}_wheel">
	    <hardwareInterface>hardware_interface/VelocityJointInterface</hardwareInterface>
	  </joint>
	</transmission>

  <gazebo reference="${wheel_prefix}_wheel_link">
	  <mu1 value="0.8"/>
	  <mu2 value="0.8"/>
	  <kp value="10000000.0" />
	  <kd value="1.0" />
	  <fdir1 value="1 0 0"/>
	</gazebo>
  </xacro:macro>
</robot>
